<?xml version="1.0"?>
<robot xmlns:xacro="http://www.ros.org/wiki/xacro" name="example">
    <link name="link_0">
        <visual>
            <origin rpy="0 0 0" xyz="0.0 0.0 0.0" />
            <geometry>
                <mesh filename="package://example_description/meshes/link_0.stl" />
            </geometry>
        </visual>
    </link>

    <link name="link_1">
        <visual>
            <origin rpy="0 0 0" xyz="0 0 0.2" />
            <geometry>
                <mesh filename="package://example_description/meshes/link_1.stl" />
            </geometry>
        </visual>
    </link>

    <joint name="link_0_to_link_1" type="revolute">
        <parent link="link_0" />
        <child link="link_1" />
        <limit effort="1000.0" lower="0.0" upper="6.28" velocity="0.5" />
        <axis xyz="0 0 1" />
        <origin xyz="0 0 0" rpy="0 0 0"/>
    </joint>

    <link name="link_2">
        <visual>
            <origin rpy="3.1415 0 0" xyz="0 0 0" />
            <geometry>
                <mesh filename="package://example_description/meshes/link_2.stl" />
            </geometry>
        </visual>
    </link>

    <joint name="link_1_to_link_2" type="revolute">
        <parent link="link_1" />
        <child link="link_2" />
        <limit effort="1000.0" lower="1.5708" upper="4.7108" velocity="0.5" />
        <axis xyz="0 0 1" />
        <origin xyz="0 -0.12 0.2" rpy="1.5708 1.5708 0" />
    </joint>

    <link name="link_3">
        <visual>
            <origin rpy="0 0 0" xyz="0.0 0 0" />
            <geometry>
                <mesh filename="package://example_description/meshes/link_3.stl" />
            </geometry>
        </visual>
    </link>

    <joint name="link_2_to_link_3" type="revolute">
        <parent link="link_2" />
        <child link="link_3" />
        <limit effort="1000.0" lower="-3.1415" upper="3.1415" velocity="0.5" />
        <axis xyz="0 0 1" />
        <origin xyz="0.25 0 -0.1" rpy="3.1415 0 0" />
    </joint>

    <link name="end_effector">
        <visual>
            <origin rpy="0 0 0" xyz="0.0 0 0.125" />
            <geometry>
                <mesh filename="package://example_description/meshes/end_effector.stl" />
            </geometry>
        </visual>
    </link>

    <joint name="link_3_to_end_effector" type="revolute">
        <parent link="link_3" />
        <child link="end_effector" />
        <limit effort="1000.0" lower="-3.14" upper="3.14" velocity="0.5" />
        <axis xyz="0 0 1" />
        <origin xyz="0.15 0 0" rpy="0  1.5708 0" />
    </joint>

</robot>